import { render, screen } from '@testing-library/react';
import { vi } from 'vitest';
import ErrorBoundary from './ErrorBoundary';

const ErrorProneComponent = () => {
  throw new Error('Test error');
};

describe('ErrorBoundary Component', () => {
  it('renders children when there is no error', () => {
    render(
      <ErrorBoundary>
        <div>Child Component</div>
      </ErrorBoundary>
    );

    expect(screen.getByText('Child Component')).toBeInTheDocument();
  });

  it('displays fallback UI when an error is thrown', () => {
    render(
      <ErrorBoundary>
        <ErrorProneComponent />
      </ErrorBoundary>
    );

    expect(screen.getByText('Something went wrong ðŸ˜ž')).toBeInTheDocument();
    expect(screen.getByText('Please try again later.')).toBeInTheDocument();
    expect(screen.getByText('Reload App')).toBeInTheDocument();
  });

  it('calls componentDidCatch and logs error when an error occurs', () => {
    const consoleSpy = vi.spyOn(console, 'error').mockImplementation(() => {});

    render(
      <ErrorBoundary>
        <ErrorProneComponent />
      </ErrorBoundary>
    );

    expect(consoleSpy).toHaveBeenCalled();
    consoleSpy.mockRestore();
  });
});
